Workbook

Sheet SRC Q1 2026 winners
A1: Quarter | B1: Country key | C1: ASC Code | D1: ASC Name | E1: Engineer | F1: SVC Type | G1: SBA ID | H1: SSR | I1: REDO | J1: Chatbot | K1: HASS | L1: Acc Core Parts (VD) | M1: Training Attendance | N1: Linkage ratio | O1: Final Score
A2: Q1 | B2: EG | C2: 4969684 | D2: K-ELECTRONICS MARSA | E2: 7886002522 | F2: IH | G2: GSPN.shady_moustafa20 | H2: 1 | I2: 1 | J2: 0 | K2: 1 | L2: 0.5 | M2: 1 | N2: 1 | O2: 110
A3: Q1 | B3: EG | C3: 4969685 | D3: K-ELECTRONICS ELIBRA | E3: 7886002532 | F3: IH | G3: GSPN.emad_metry20 | H3: 1 | I3: 0 | J3: 1 | K3: 0.975 | L3: 0.125 | M3: 1 | N3: 1 | O3: 110
A4: Q1 | B4: EG | C4: 5933773 | D4: TIBA FOR TRADE AND M | E4: 7886002529 | F4: IH | G4: GSPN.AhmedShakerTiba | H4: 1 | I4: 1 | J4: 0 | K4: 1 | L4: 0 | M4: 1 | N4: 1 | O4: 110
A5: Q1 | B5: EG | C5: 4969685 | D5: K-ELECTRONICS ELIBRA | E5: 7886002535 | F5: PR | G5: GSPN.mohamed_saleh20 | H5: 1 | I5: 1 | J5: 0.333 | K5: 0 | L5: 0 | M5: 1 | N5: 1 | O5: 100
A6: Q1 | B6: EG | C6: 8396105 | D6: TO CONNECT SHOP/ | E6: 7886000919 | F6: IH | G6: GSPN.M.hussein2000 | H6: 1 | I6: 1 | J6: 0 | K6: 0 | L6: 0.11111111 | M6: 1 | N6: 1 | O6: 95
A7: Q1 | B7: EG | C7: 9203499 | D7: HI TECH FOR MAINTENA | E7: 7886001034 | F7: IH | G7: GSPN.HiAshrafZag010 | H7: 1 | I7: 1 | J7: 0 | K7: 0 | L7: 0 | M7: 1 | N7: 1 | O7: 95
A8: Q1 | B8: EG | C8: 9390474 | D8: EGYPTIAN MICRO SOLUT | E8: 7886002144 | F8: IH | G8: GSPN.elshayeb2021 | H8: 1 | I8: 1 | J8: 0 | K8: 0 | L8: 0 | M8: 1 | N8: 1 | O8: 95
A9: Q1 | B9: EG | C9: 2490932 | D9: ADEL CENTER BANI SUE | E9: 7886002061 | F9: IH | G9: GSPN.naderdiab2020 | H9: 1 | I9: 1 | J9: 0 | K9: 1 | L9: 0 | M9: 0 | N9: 1 | O9: 90
A10: Q1 | B10: EG | C10: 2490932 | D10: ADEL CENTER BANI SUE | E10: 7886002661 | F10: IH | G10: No SBA ID | H10: 1 | I10: 1 | J10: 0 | K10: 1 | L10: 0 | M10: No History | N10: 1 | O10: 90
A11: Q1 | B11: EG | C11: 4970875 | D11: ELECTRA ASSUIT/ | E11: 7886002673 | F11: IH | G11: GSPN.mahmoudgaber2023 | H11: 1 | I11: 1 | J11: 0 | K11: 1 | L11: 0 | M11: 0 | N11: 1 | O11: 90
A12: Q1 | B12: EG | C12: 4970875 | D12: ELECTRA ASSUIT/ | E12: 7886002844 | F12: IH | G12: GSPN.mmeneem2025 | H12: 1 | I12: 1 | J12: 0 | K12: 1 | L12: 0.058823529 | M12: 0 | N12: 1 | O12: 90
A13: Q1 | B13: EG | C13: 5797728 | D13: ELECTRA GIZA/ | E13: 7886002491 | F13: IH | G13: GSPN.WaelHassan | H13: 1 | I13: 1 | J13: 1 | K13: 0.92307692 | L13: 0 | M13: No History | N13: 1 | O13: 90
A14: Q1 | B14: EG | C14: 9203497 | D14: U TECH FOR SERVICE & | E14: 7886002470 | F14: IH | G14: GSPN.omar_wadye | H14: 1 | I14: 1 | J14: 0 | K14: 1 | L14: 0 | M14: No History | N14: 1 | O14: 90
A15: Q1 | B15: EG | C15: 9203501 | D15: RAMY EL TABIE ABDO G | E15: 7886002565 | F15: IH | G15: GSPN.Mostafahelaly24 | H15: 1 | I15: 1 | J15: 0 | K15: 1 | L15: 0 | M15: No History | N15: 1 | O15: 90
A16: Q1 | B16: EG | C16: 8351903 | D16: NANOTEC/ | E16: 7886000279 | F16: IH | G16: GSPN.nanotechesa1 | H16: 1 | I16: 1 | J16: 0 | K16: 1 | L16: 0 | M16: 0.5 | N16: 1 | O16: 85
A17: Q1 | B17: EG | C17: 1390788 | D17: ATS BE - GREAT CAIRO | E17: 7886002136 | F17: IH | G17: GSPN.asalem | H17: 1 | I17: 1 | J17: 0 | K17: 0 | L17: 0.2 | M17: 0.5 | N17: 1 | O17: 85
A18: Q1 | B18: EG | C18: 1390788 | D18: ATS BE - GREAT CAIRO | E18: 7886002360 | F18: PR | G18: GSPN.osamaf | H18: 1 | I18: 1 | J18: 0 | K18: 0 | L18: 0 | M18: 0.5 | N18: 1 | O18: 85
A19: Q1 | B19: EG | C19: 1390788 | D19: ATS BE - GREAT CAIRO | E19: 7886002410 | F19: PR | G19: GSPN.Soltans | H19: 1 | I19: 1 | J19: 0 | K19: 0 | L19: 0 | M19: 0.5 | N19: 1 | O19: 85
A20: Q1 | B20: EG | C20: 8351903 | D20: NANOTEC/ | E20: 7886001745 | F20: IH | G20: GSPN.aismaiel | H20: 1 | I20: 1 | J20: 0.667 | K20: 1 | L20: 0 | M20: No History | N20: 1 | O20: 85
A21: Q1 | B21: EG | C21: 8351903 | D21: NANOTEC/ | E21: 7886002009 | F21: IH | G21: GSPN.Mokhtarabdelrahim1 | H21: 1 | I21: 1 | J21: 0.667 | K21: 1 | L21: 0 | M21: 0 | N21: 1 | O21: 85
A22: Q1 | B22: EG | C22: 9372701 | D22: RAYA GIZA (HA)/ | E22: 7886002429 | F22: PR | G22: GSPN.HiDoharyZag011 | H22: 1 | I22: 1 | J22: 0.333 | K22: 1 | L22: 0 | M22: No History | N22: 1 | O22: 80
A23: Q1 | B23: EG | C23: 8351903 | D23: NANOTEC/ | E23: 7886002099 | F23: IH | G23: GSPN.KaremAV | H23: 1 | I23: 1 | J23: 0 | K23: 0 | L23: 0 | M23: 0.5 | N23: 1 | O23: 85
A24: Q1 | B24: EG | C24: 9203499 | D24: HI TECH FOR MAINTENA | E24: 7886002432 | F24: IH | G24: GSPN.HiShawkyZag | H24: 1 | I24: 1 | J24: 0.667 | K24: 0.85714286 | L24: 0 | M24: No History | N24: 1 | O24: 85
A25: Q1 | B25: EG | C25: 4162738 | D25: ELECTRA/ | E25: 7886002743 | F25: IH | G25: GSPN.AhmedEzzatZaki | H25: 1 | I25: 1 | J25: 0.333 | K25: 0.73684211 | L25: 0 | M25: No History | N25: 1 | O25: 78.003096
A26: Q1 | B26: EG | C26: 9203499 | D26: HI TECH FOR MAINTENA | E26: 7886001055 | F26: IH | G26: GSPN.HiRamdanZag | H26: 1 | I26: 1 | J26: 0.333 | K26: 0.66666667 | L26: 0 | M26: No History | N26: 1 | O26: 76.764706
A27: Q1 | B27: EG | C27: 9203507 | D27: ADEL MALAK TERIAK/ | E27: 7886000680 | F27: IH | G27: GSPN.MICHAELADEL | H27: 1 | I27: 0 | J27: 0 | K27: 1 | L27: 0 | M27: 0 | N27: 1 | O27: 75
A28: Q1 | B28: EG | C28: 1390788 | D28: ATS BE - GREAT CAIRO | E28: 7886002683 | F28: IH | G28: GSPN.gomaamohamed | H28: 1 | I28: 1 | J28: 0 | K28: 0 | L28: 0 | M28: No History | N28: 1 | O28: 75
A29: Q1 | B29: EG | C29: 2226596 | D29: TO CONNECT - NAG HAM | E29: 7886002401 | F29: IH | G29: GSPN.Mohamed_Hussein_2022 | H29: 1 | I29: 1 | J29: 0 | K29: 0 | L29: 0 | M29: 0 | N29: 1 | O29: 75
A30: Q1 | B30: EG | C30: 2278119 | D30: RAYA - MANSOURA/ | E30: 7886002386 | F30: IH | G30: GSPN.mostafa_attia01 | H30: 1 | I30: 1 | J30: 0 | K30: 0 | L30: 0.12820513 | M30: 0 | N30: 1 | O30: 75
A31: Q1 | B31: EG | C31: 2490932 | D31: ADEL CENTER BANI SUE | E31: 7886002660 | F31: IH | G31: No SBA ID | H31: 1 | I31: 1 | J31: 0 | K31: 0 | L31: 0 | M31: No History | N31: 1 | O31: 75
A32: Q1 | B32: EG | C32: 3489862 | D32: RAYA - GHARBEYA/ | E32: 7086001106 | F32: IH | G32: GSPN.loay_elabasy24 | H32: 1 | I32: 1 | J32: 0 | K32: 0 | L32: 0.11111111 | M32: No History | N32: 1 | O32: 75
A33: Q1 | B33: EG | C33: 4162738 | D33: ELECTRA/ | E33: 7886002670 | F33: IH | G33: No SBA ID | H33: 1 | I33: 1 | J33: 0 | K33: 0 | L33: 0 | M33: No History | N33: 1 | O33: 75
A34: Q1 | B34: EG | C34: 4162738 | D34: ELECTRA/ | E34: 7886002792 | F34: IH | G34: GSPN.TareKMAbuAKhair | H34: 1 | I34: 1 | J34: 0 | K34: 0 | L34: 0 | M34: 0 | N34: 1 | O34: 75
A35: Q1 | B35: EG | C35: 4162738 | D35: ELECTRA/ | E35: 7886002794 | F35: IH | G35: GSPN.HamedSaad | H35: 1 | I35: 1 | J35: 0 | K35: 0 | L35: 0 | M35: 0 | N35: 1 | O35: 75
A36: Q1 | B36: EG | C36: 4970875 | D36: ELECTRA ASSUIT/ | E36: 7886002675 | F36: IH | G36: GSPN.mohamedmoheb15 | H36: 1 | I36: 1 | J36: 0 | K36: 0 | L36: 0.29411765 | M36: No History | N36: 1 | O36: 75
A37: Q1 | B37: EG | C37: 5797725 | D37: HI TECH TANTA/ | E37: 7886002538 | F37: IH | G37: GSPN.Hatemagamy | H37: 1 | I37: 1 | J37: 0 | K37: 1 | L37: 0 | M37: No History | N37: 1 | O37: 75
A38: Q1 | B38: EG | C38: 5797725 | D38: HI TECH TANTA/ | E38: 7886002539 | F38: IH | G38: GSPN.Ahmedhamouda | H38: 1 | I38: 1 | J38: 0 | K38: 1 | L38: 0 | M38: No History | N38: 1 | O38: 75
A39: Q1 | B39: EG | C39: 5797725 | D39: HI TECH TANTA/ | E39: 7886002540 | F39: CI | G39: GSPN.Ahmedmatar | H39: 1 | I39: 1 | J39: 0 | K39: 1 | L39: 0 | M39: No History | N39: 1 | O39: 75
A40: Q1 | B40: EG | C40: 5797725 | D40: HI TECH TANTA/ | E40: 7886002543 | F40: IH | G40: GSPN.mohammedeldebeky | H40: 1 | I40: 1 | J40: 0 | K40: 1 | L40: 0 | M40: No History | N40: 1 | O40: 75
...

Sheet SRC Q2 Engineer Eval
A1: SUB | B1: Country key | C1: W/B Partner | D1: ASC Name | E1: Target For Evaluation Yes No | G1: Engineer | H1: Status | I1: SVC Type | J1: Dedicated/Non Dedicated | K1: SBA ID | L1: SBA ID Status | M1: Major/Minor | N1: Eng Code Status | O1: Product Group | P1: Acc Wrty Volume | Q1: Rep or Install Eng | R1: Redo | S1: Training Att | T1: RNPS | U1: S.T con | V1: MJ % | W1: Comp. Repair | X1: Hass | Y1: Kahoot | Z1: Redo | AA1: Training Att | AB1: RNPS | AC1: S.T con | AD1: MJ % | AE1: Comp. Repair | AF1: Kahoot | AG1: Total | AH1: Hass | AI1: Repair Volume | AJ1: Q2 Final Result
A2: SEEG | B2: EG | C2: 4969684 | D2: K-ELECTRONICS MARSA | E2: Target | F2: MSC | G2: 7886002522 | H2: Excluded Q4 & Q1 | I2: IH | J2: Dedicated | K2: GSPN.shady_moustafa20 | L2: Active | M2: Below 20 | N2: W | O2: AV | P2: 87 | Q2: Repair | R2: 1 | S2: 1 | T2: 100 | U2: 1 | V2: 0.0044247788 | W2: 1 | X2: 1 | Z2: 15 | AA2: 15 | AB2: 20 | AC2: 15 | AD2: 15 | AE2: 15 | AG2: 95 | AH2: 15 | AI2: 118.75 | AJ2: 133.75
A3: SEEG | B3: EG | C3: 4970875 | D3: ELECTRA ASSUIT/ | E3: Target | F3: MSC | G3: 7886002844 | H3: Excluded Q4 & Q1 | I3: IH | J3: Dedicated | K3: GSPN.mmeneem2025 | L3: Active | M3: Below 20 | N3: W | O3: AV + HA | P3: 115 | Q3: Repair | R3: 1 | S3: 1 | T3: 66.666667 | U3: 0.5 | V3: 0.011061947 | W3: 1 | X3: 0.75 | Z3: 15 | AA3: 15 | AB3: 18 | AC3: 7.5 | AD3: 15 | AE3: 15 | AG3: 85.5 | AH3: 11.25 | AI3: 106.875 | AJ3: 118.125
A4: SEEG | B4: EG | C4: 5933773 | D4: TIBA FOR TRADE AND M | E4: Target | F4: MSC | G4: 7886002529 | H4: Excluded Q4 & Q1 | I4: IH | J4: Dedicated | K4: GSPN.AhmedShakerTiba | L4: Active | M4: Below 20 | N4: W | O4: AV | P4: 400 | Q4: Repair | R4: 1 | S4: 1 | T4: 100 | U4: 0 | V4: 0.017699115 | W4: 1 | X4: 1 | Z4: 15 | AA4: 15 | AB4: 20 | AC4: 0 | AD4: 15 | AE4: 15 | AG4: 80 | AH4: 15 | AI4: 100 | AJ4: 115
A5: SEEG | B5: EG | C5: 8351903 | D5: NANOTEC/ | E5: Target | F5: MSC | G5: 7886002084 | H5: Excluded Q4 & Q1 | I5: IH | J5: Dedicated | K5: GSPN.mohamedmahros1 | L5: Active | M5: Below 20 | N5: W | O5: HA | P5: 143 | Q5: Repair | R5: 1 | S5: 1 | T5: 100 | U5: 1 | V5: 0.011061947 | W5: 0 | X5: 1 | Z5: 15 | AA5: 15 | AB5: 20 | AC5: 15 | AD5: 15 | AE5: 0 | AG5: 80 | AH5: 15 | AI5: 100 | AJ5: 115
A6: SEEG | B6: EG | C6: 4969681 | D6: K-ELECTRONICS KAFR E | E6: Target | F6: MSC | G6: 7886002521 | H6: Included | I6: IH | J6: Dedicated | K6: GSPN.mohamed_raslan20 | L6: Active | M6: Below 20 | N6: W | O6: AV + HA | P6: 226 | Q6: Repair | R6: 1 | S6: 1 | T6: 84.210526 | U6: 0 | V6: 0.017699115 | W6: 1 | X6: 1 | Z6: 15 | AA6: 15 | AB6: 20 | AC6: 0 | AD6: 15 | AE6: 15 | AG6: 80 | AH6: 15 | AI6: 100 | AJ6: 115
A7: SEEG | B7: EG | C7: 4969681 | D7: K-ELECTRONICS KAFR E | E7: Target | F7: MSC | G7: 7886002530 | H7: Included | I7: IH | J7: Dedicated | K7: GSPN.mohamed_fawzy20 | L7: active | M7: Below 20 | N7: W | O7: AV + HA | P7: 40 | Q7: Repair | R7: 1 | S7: 1 | T7: 71.428571 | U7: 0 | V7: 0.015486726 | W7: 1 | X7: 1 | Z7: 15 | AA7: 15 | AB7: 20 | AC7: 0 | AD7: 15 | AE7: 15 | AG7: 80 | AH7: 15 | AI7: 100 | AJ7: 115
A8: SEEG | B8: EG | C8: 8351903 | D8: NANOTEC/ | E8: Target | F8: MSC | G8: 7886002009 | H8: Excluded Q4 & Q1 | I8: IH | J8: Dedicated | K8: GSPN.Mokhtarabdelrahim1 | L8: Active | M8: Below 20 | N8: W | O8: HA | P8: 83 | Q8: Repair | R8: 1 | S8: 1 | T8: 100 | U8: 0.77777778 | V8: 0.0044247788 | W8: 0 | X8: 0.90909091 | Z8: 15 | AA8: 15 | AB8: 20 | AC8: 11.666667 | AD8: 15 | AE8: 0 | AG8: 76.666667 | AH8: 13.636364 | AI8: 95.833333 | AJ8: 109.4697
A9: SEEG | B9: EG | C9: 8351903 | D9: NANOTEC/ | E9: Target | F9: MSC | G9: 7886002215 | H9: Included | I9: IH | J9: Dedicated | K9: GSPN.KaremGamal | L9: Active | M9: Below 20 | N9: W | O9: HA | P9: 63 | Q9: Repair | R9: 1 | S9: 1 | T9: 87.5 | U9: 0.68181818 | V9: 0.0066371681 | W9: 0 | X9: 1 | Z9: 15 | AA9: 15 | AB9: 20 | AC9: 10.227273 | AD9: 15 | AE9: 0 | AG9: 75.227273 | AH9: 15 | AI9: 94.034091 | AJ9: 109.03409
A10: SEEG | B10: EG | C10: 9372701 | D10: RAYA GIZA (HA)/ | E10: Target | F10: MSC | G10: 7886002672 | H10: Included | I10: PR | J10: Dedicated | K10: GSPN.ahmedrdwan | L10: Active | M10: Above 20 | N10: Not Found | O10: HA | P10: 26 | Q10: Installation | R10: 1 | S10: 1 | T10: 100 | U10: 0.5 | V10: 0.0044247788 | W10: 0 | X10: 1 | Z10: 15 | AA10: 15 | AB10: 20 | AC10: 7.5 | AD10: 15 | AE10: 0 | AG10: 72.5 | AH10: 15 | AI10: 90.625 | AJ10: 105.625
A11: SEEG | B11: EG | C11: 9203497 | D11: U TECH FOR SERVICE & | E11: Target | F11: MSC | G11: 7886002682 | H11: Included | I11: IH | J11: Dedicated | K11: No SBA ID | L11: InActive | M11: Above 30 | N11: W | O11: AV + HA | P11: 73 | Q11: Repair | R11: 1 | S11: 1 | T11: 100 | U11: 0.5 | V11: 1 | W11: 1 | X11: 0.85714286 | Z11: 15 | AA11: 15 | AB11: 20 | AC11: 7.5 | AD11: 0 | AE11: 15 | AG11: 72.5 | AH11: 12.857143 | AI11: 90.625 | AJ11: 103.48214
A12: SEEG | B12: EG | C12: 4969685 | D12: K-ELECTRONICS ELIBRA | E12: Target | F12: MSC | G12: 7886002532 | H12: Excluded Q4 & Q1 | I12: IH | J12: Dedicated | K12: GSPN.emad_metry20 | L12: Active | M12: Above 20 | N12: W | O12: AV | P12: 165 | Q12: Repair | R12: 1 | S12: 1 | T12: 57.142857 | U12: 0 | V12: 0.033185841 | W12: 1 | X12: 1 | Z12: 15 | AA12: 15 | AB12: 15 | AC12: 0 | AD12: 10 | AE12: 15 | AG12: 70 | AH12: 15 | AI12: 87.5 | AJ12: 102.5
A13: SEEG | B13: EG | C13: 5797728 | D13: ELECTRA GIZA/ | E13: Target | F13: MSC | G13: 7886002485 | H13: Included | I13: IH | J13: Dedicated | K13: GSPN.HaniyHassan | L13: Active | M13: Below 20 | N13: W | O13: HA | P13: 108 | Q13: Repair | R13: 1 | S13: 1 | T13: 88.461538 | U13: 1 | V13: 0.030973451 | W13: 0 | X13: 0.25 | Z13: 15 | AA13: 15 | AB13: 20 | AC13: 15 | AD13: 10 | AE13: 0 | AG13: 75 | AH13: 3.75 | AI13: 93.75 | AJ13: 97.5
... A15: SEEG | B15: EG | C15: 8351903 | D15: NANOTEC/ | E15: Target | F15: MSC | G15: 7886002762 | H15: Excluded Q4 & Q1 | I15: IH | J15: Dedicated | K15: GSPN.ahmedbelal2025 | L15: Active | M15: Below 20 | N15: W | O15: HA | P15: 75 | Q15: Repair | R15: 1 | S15: 1 | T15: 100 | U15: 0 | V15: 0.0044247788 | W15: 0 | X15: 1 | Z15: 15 | AA15: 15 | AB15: 20 | AC15: 0 | AD15: 15 | AE15: 0 | AG15: 65 | AH15: 15 | AI15: 81.25 | AJ15: 96.25
A16: SEEG | B16: EG | C16: 8398383 | D16: EL MOHANDES SERVICE | E16: Target | F16: ASC | G16: 7886000632 | H16: Included | I16: IH | J16: Non Dedicated | K16: GSPN.MohAhmed1 | L16: Active | M16: Below 20 | N16: W | O16: AV | P16: 25 | Q16: Repair | R16: 1 | S16: 1 | T16: 100 | U16: 0 | V16: 0.0022123894 | W16: 0.75 | Z16: 15 | AA16: 15 | AB16: 20 | AC16: 0 | AD16: 15 | AE16: 11.25 | AG16: 76.25 | AH16: 0 | AI16: 95.3125 | AJ16: 95.3125
A17: SEEG | B17: EG | C17: 8351903 | D17: NANOTEC/ | E17: Target | F17: MSC | G17: 7886001746 | H17: Included | I17: IH | J17: Dedicated | K17: GSPN.mafify | L17: Active | M17: Below 20 | N17: W | O17: HA | P17: 73 | Q17: Repair | R17: 1 | S17: 1 | T17: 100 | U17: 0 | V17: 0.0088495575 | W17: 0 | X17: 0.91666667 | Z17: 15 | AA17: 15 | AB17: 20 | AC17: 0 | AD17: 15 | AE17: 0 | AG17: 65 | AH17: 13.75 | AI17: 81.25 | AJ17: 95
A18: SEEG | B18: EG | C18: 5797727 | D18: HI TECH MENOFEYA/ | E18: Target | F18: MSC | G18: 7886002547 | H18: Included | I18: IH | J18: Dedicated | K18: No SBA ID | L18: InActive | M18: Below 20 | N18: W | O18: HA | P18: 72 | Q18: Repair | R18: 1 | S18: 1 | T18: 100 | U18: 0 | V18: 0.017699115 | W18: 0 | X18: 0.90909091 | Z18: 15 | AA18: 15 | AB18: 20 | AC18: 0 | AD18: 15 | AE18: 0 | AG18: 65 | AH18: 13.636364 | AI18: 81.25 | AJ18: 94.886364
A19: SEEG | B19: EG | C19: 9203497 | D19: U TECH FOR SERVICE & | E19: Target | F19: MSC | G19: 7886002439 | H19: Included | I19: IH | J19: Dedicated | K19: GSPN.karem_elbathe | L19: active | M19: Above 30 | N19: W | O19: AV + HA | P19: 197 | Q19: Repair | R19: 0 | S19: 1 | T19: 84.615385 | U19: 0 | V19: 0.0066371681 | W19: 1 | X19: 0.86363636 | Z19: 0 | AA19: 15 | AB19: 20 | AC19: 0 | AD19: 15 | AE19: 15 | AG19: 65 | AH19: 12.954545 | AI19: 81.25 | AJ19: 94.204545
A20: SEEG | B20: EG | C20: 5797725 | D20: HI TECH TANTA/ | E20: Target | F20: MSC | G20: 7886002542 | H20: Included | I20: IH | J20: Dedicated | K20: No SBA ID | L20: InActive | M20: Below 20 | N20: W | O20: HA | P20: 29 | Q20: Repair | R20: 1 | S20: 1 | T20: 100 | U20: 0 | V20: 0.019911504 | W20: 0 | X20: 0.75 | Z20: 15 | AA20: 15 | AB20: 20 | AC20: 0 | AD20: 15 | AE20: 0 | AG20: 65 | AH20: 11.25 | AI20: 81.25 | AJ20: 92.5
A21: SEEG | B21: EG | C21: 8351903 | D21: NANOTEC/ | E21: Target | F21: MSC | G21: 7886002788 | H21: Included | I21: IH | J21: Dedicated | K21: No SBA ID | L21: InActive | M21: Below 20 | N21: W | O21: HA | P21: 76 | Q21: Repair | R21: 0 | S21: 1 | T21: 100 | U21: 1 | V21: 0.011061947 | W21: 0 | X21: 0.7 | Z21: 0 | AA21: 15 | AB21: 20 | AC21: 15 | AD21: 15 | AE21: 0 | AG21: 65 | AH21: 10.5 | AI21: 81.25 | AJ21: 91.75
A22: SEEG | B22: EG | C22: 9203499 | D22: HI TECH FOR MAINTENA | E22: Target | F22: MSC | G22: 7886001055 | H22: Included | I22: IH | J22: Dedicated | K22: GSPN.HiRamdanZag | L22: Active | M22: Above 30 | N22: W | O22: HA | P22: 122 | Q22: Repair | R22: 1 | S22: 1 | T22: 100 | U22: 0 | V22: 0.017699115 | W22: 0 | X22: 0.6875 | Z22: 15 | AA22: 15 | AB22: 20 | AC22: 0 | AD22: 15 | AE22: 0 | AG22: 65 | AH22: 10.3125 | AI22: 81.25 | AJ22: 91.5625
A23: SEEG | B23: EG | C23: 5797729 | D23: TECH VALLEY MANSOURA | E23: Target | F23: MSC | G23: 7886002501 | H23: Included | I23: IH | J23: Dedicated | K23: GSPN.AhmedAhmedAbuAlmaati94 | L23: active | M23: Below 20 | N23: W | O23: HA | P23: 144 | Q23: Repair | R23: 1 | S23: 1 | T23: 100 | U23: 0 | V23: 0.024336283 | W23: 0 | X23: 1 | Z23: 15 | AA23: 15 | AB23: 20 | AC23: 0 | AD23: 10 | AE23: 0 | AG23: 60 | AH23: 15 | AI23: 75 | AJ23: 90
A24: SEEG | B24: EG | C24: 5189455 | D24: AHMED EL SAYED ABDO | E24: Target | F24: ASC | G24: 7886002436 | H24: Included | I24: IH | J24: Non Dedicated | K24: GSPN.ahmedelaraby | L24: Active | M24: Above 20 | N24: W | O24: AV + HA | P24: 517 | Q24: Repair | R24: 0 | S24: 1 | T24: 81.818182 | U24: 1 | V24: 0.044247788 | W24: 1 | X24: 0.014084507 | Z24: 0 | AA24: 15 | AB24: 20 | AC24: 15 | AD24: 5 | AE24: 15 | AG24: 70 | AH24: 0.21126761 | AI24: 87.5 | AJ24: 87.711268
A25: SEEG | B25: EG | C25: 5797725 | D25: HI TECH TANTA/ | E25: Target | F25: MSC | G25: 7886002540 | H25: Included | I25: CI | J25: Dedicated | K25: GSPN.Ahmedmatar | L25: active | M25: Below 20 | N25: W | O25: HA | P25: 51 | Q25: Repair | R25: 1 | S25: 1 | T25: 0 | U25: 0.75 | V25: 0.0022123894 | W25: 0 | X25: 1 | Z25: 15 | AA25: 15 | AB25: 0 | AC25: 11.25 | AD25: 15 | AE25: 0 | AG25: 56.25 | AH25: 15 | AI25: 70.3125 | AJ25: 85.3125
A26: SEEG | B26: EG | C26: 8351903 | D26: NANOTEC/ | E26: Target | F26: MSC | G26: 7886001214 | H26: Included | I26: IH | J26: Dedicated | K26: No SBA ID | L26: InActive | M26: Below 20 | N26: W | O26: HA | P26: 144 | Q26: Repair | R26: 0 | S26: 1 | T26: 100 | U26: 0 | V26: 0.042035398 | W26: 1 | X26: 0.95 | Z26: 0 | AA26: 15 | AB26: 20 | AC26: 0 | AD26: 5 | AE26: 15 | AG26: 55 | AH26: 14.25 | AI26: 68.75 | AJ26: 83
A27: SEEG | B27: EG | C27: 1390788 | D27: ATS BE - GREAT CAIRO | E27: Target | F27: MSC | G27: 7886002136 | H27: Excluded Q4 & Q1 | I27: IH | J27: Dedicated | K27: GSPN.asalem | L27: Active | M27: Above 30 | N27: W | O27: AV | P27: 25 | Q27: Repair | R27: 1 | S27: 1 | T27: 100 | U27: 0 | V27: 1 | W27: 1 | Z27: 15 | AA27: 15 | AB27: 20 | AC27: 0 | AD27: 0 | AE27: 15 | AG27: 65 | AH27: 0 | AI27: 81.25 | AJ27: 81.25
A28: SEEG | B28: EG | C28: 8351903 | D28: NANOTEC/ | E28: Target | F28: MSC | G28: 7886002099 | H28: Excluded Q4 & Q1 | I28: IH | J28: Dedicated | K28: GSPN.KaremAV | L28: Active | M28: Below 20 | N28: W | O28: AV | P28: 66 | Q28: Repair | R28: 1 | S28: 1 | T28: 85.714286 | U28: 0 | V28: 1 | W28: 1 | Z28: 15 | AA28: 15 | AB28: 20 | AC28: 0 | AD28: 0 | AE28: 15 | AG28: 65 | AH28: 0 | AI28: 81.25 | AJ28: 81.25
A29: SEEG | B29: EG | C29: 1390788 | D29: ATS BE - GREAT CAIRO | E29: Target | F29: MSC | G29: 7886002683 | H29: Included | I29: IH | J29: Dedicated | K29: GSPN.gomaamohamed | L29: Active | M29: Above 30 | N29: W | O29: AV | P29: 59 | Q29: Repair | R29: 1 | S29: 1 | T29: 85.714286 | U29: 0 | V29: 1 | W29: 1 | Z29: 15 | AA29: 15 | AB29: 20 | AC29: 0 | AD29: 0 | AE29: 15 | AG29: 65 | AH29: 0 | AI29: 81.25 | AJ29: 81.25
A30: SEEG | B30: EG | C30: 2278119 | D30: RAYA - MANSOURA/ | E30: Target | F30: MSC | G30: 7886002386 | H30: Included | I30: IH | J30: Dedicated | K30: GSPN.mostafa_attia01 | L30: Active | M30: Above 30 | N30: W | O30: AV | P30: 22 | Q30: Repair | R30: 1 | S30: 1 | T30: 100 | U30: 0 | V30: 1 | W30: 1 | Z30: 15 | AA30: 15 | AB30: 20 | AC30: 0 | AD30: 0 | AE30: 15 | AG30: 65 | AH30: 0 | AI30: 81.25 | AJ30: 81.25
A31: SEEG | B31: EG | C31: 8351903 | D31: NANOTEC/ | E31: Target | F31: MSC | G31: 7886000279 | H31: Excluded Q4 & Q1 | I31: IH | J31: Dedicated | K31: GSPN.nanotechesa1 | L31: Active | M31: Below 20 | N31: W | O31: HA | P31: 94 | Q31: Repair | R31: 1 | S31: 1 | T31: 100 | U31: 0.1 | V31: 1 | W31: 0 | X31: 1 | Z31: 15 | AA31: 15 | AB31: 20 | AC31: 1.5 | AD31: 0 | AE31: 0 | AG31: 51.5 | AH31: 15 | AI31: 64.375 | AJ31: 79.375
A32: SEEG | B32: EG | C32: 3489862 | D32: RAYA - GHARBEYA/ | E32: Target | F32: MSC | G32: 7086001106 | H32: Included | I32: IH | J32: Dedicated | K32: GSPN.loay_elabasy24 | L32: Active | M32: Above 30 | N32: I | O32: AV | P32: 110 | Q32: Repair | R32: 1 | S32: 1 | T32: 100 | U32: 0 | V32: 1 | W32: 1 | Z32: 15 | AA32: 15 | AB32: 20 | AC32: 0 | AD32: 0 | AE32: 15 | AG32: 65 | AH32: 0 | AI32: 81.25 | AJ32: 81.25
A33: SEEG | B33: EG | C33: 4970875 | D33: ELECTRA ASSUIT/ | E33: Target | F33: MSC | G33: 7886002675 | H33: Excluded Q4 & Q1 | I33: IH | J33: Dedicated | K33: GSPN.mohamedmoheb15 | L33: Active | M33: Below 20 | N33: W | O33: AV | P33: 41 | Q33: Repair | R33: 1 | S33: 1 | T33: 100 | U33: 0 | V33: 1 | W33: 1 | Z33: 15 | AA33: 15 | AB33: 20 | AC33: 0 | AD33: 0 | AE33: 15 | AG33: 65 | AH33: 0 | AI33: 81.25 | AJ33: 81.25
A34: SEEG | B34: EG | C34: 9203499 | D34: HI TECH FOR MAINTENA | E34: Target | F34: MSC | G34: 7886001034 | H34: Excluded Q4 & Q1 | I34: IH | J34: Dedicated | K34: GSPN.HiAshrafZag010 | L34: Active | M34: Above 30 | N34: I | O34: AV | P34: 22 | Q34: Repair | R34: 1 | S34: 1 | T34: 100 | U34: 0 | V34: 1 | W34: 1 | Z34: 15 | AA34: 15 | AB34: 20 | AC34: 0 | AD34: 0 | AE34: 15 | AG34: 65 | AH34: 0 | AI34: 81.25 | AJ34: 81.25
A35: SEEG | B35: EG | C35: 8351903 | D35: NANOTEC/ | E35: Target | F35: MSC | G35: 7886002764 | H35: Included | I35: IH | J35: Dedicated | K35: No SBA ID | L35: InActive | M35: Below 20 | N35: W | O35: AV | P35: 47 | Q35: Repair | R35: 1 | S35: 1 | T35: 70 | U35: 0 | V35: 1 | W35: 1 | Z35: 15 | AA35: 15 | AB35: 20 | AC35: 0 | AD35: 0 | AE35: 15 | AG35: 65 | AH35: 0 | AI35: 81.25 | AJ35: 81.25
A36: SEEG | B36: EG | C36: 8351903 | D36: NANOTEC/ | E36: Target | F36: MSC | G36: 7886002765 | H36: Included | I36: IH | J36: Dedicated | K36: No SBA ID | L36: InActive | M36: Below 20 | N36: W | O36: AV | P36: 40 | Q36: Repair | R36: 1 | S36: 1 | T36: 85.714286 | U36: 0 | V36: 1 | W36: 1 | Z36: 15 | AA36: 15 | AB36: 20 | AC36: 0 | AD36: 0 | AE36: 15 | AG36: 65 | AH36: 0 | AI36: 81.25 | AJ36: 81.25
A37: SEEG | B37: EG | C37: 8215895 | D37: RAYA CAIRO/ | E37: Target | F37: MSC | G37: 7886001393 | H37: Excluded Q4 & Q1 | I37: IH | J37: Dedicated | K37: GSPN.mahmoudzaher | L37: Active | M37: Above 30 | N37: W | O37: AV | P37: 274 | Q37: Repair | R37: 1 | S37: 1 | T37: 80.769231 | U37: 0 | V37: 1 | W37: 1 | Z37: 15 | AA37: 15 | AB37: 20 | AC37: 0 | AD37: 0 | AE37: 15 | AG37: 65 | AH37: 0 | AI37: 81.25 | AJ37: 81.25
A38: SEEG | B38: EG | C38: 2278119 | D38: RAYA - MANSOURA/ | E38: Target | F38: MSC | G38: 7886002383 | H38: Included | I38: IH | J38: Dedicated | K38: GSPN.ahmed_hassan01 | L38: Active | M38: Above 30 | N38: W | O38: AV | P38: 48 | Q38: Repair | R38: 1 | S38: 1 | T38: 100 | U38: 0 | V38: 1 | W38: 1 | Z38: 15 | AA38: 15 | AB38: 20 | AC38: 0 | AD38: 0 | AE38: 15 | AG38: 65 | AH38: 0 | AI38: 81.25 | AJ38: 81.25
A39: SEEG | B39: EG | C39: 3489862 | D39: RAYA - GHARBEYA/ | E39: Target | F39: MSC | G39: 7886002384 | H39: Included | I39: IH | J39: Dedicated | K39: GSPN.khaled_yehia01 | L39: Active | M39: Above 30 | N39: W | O39: AV | P39: 145 | Q39: Repair | R39: 1 | S39: 1 | T39: 79.166667 | U39: 0 | V39: 1 | W39: 1 | Z39: 15 | AA39: 15 | AB39: 20 | AC39: 0 | AD39: 0 | AE39: 15 | AG39: 65 | AH39: 0 | AI39: 81.25 | AJ39: 81.25
A40: SEEG | B40: EG | C40: 9203500 | D40: HI TECH FOR MAINTENA | E40: Target | F40: ASC | G40: 7886002667 | H40: Included | I40: IH | J40: Non Dedicated | K40: No SBA ID | L40: InActive | M40: Below 20 | N40: W | O40: AV + HA | P40: 142 | Q40: Repair | R40: 1 | S40: 1 | T40: 15.384615 | U40: 0.25 | V40: 0.022123894 | W40: 0.91666667 | X40: 0.6 | Z40: 15 | AA40: 15 | AB40: 0 | AC40: 3.75 | AD40: 10 | AE40: 13.75 | AG40: 57.5 | AH40: 9 | AI40: 71.875 | AJ40: 80.875
A41: SEEG | B41: EG | C41: 9203499 | D41: HI TECH FOR MAINTENA | E41: Target | F41: MSC | G41: 7886002795 | H41: Included | I41: IH | J41: Dedicated | K41: GSPN.Hiadhamzag011 | L41: Active | M41: Above 30 | N41: W | O41: AV | P41: 104 | Q41: Repair | R41: 1 | S41: 1 | T41: 90 | U41: 0 | V41: 1 | W41: 0.96153846 | Z41: 15 | AA41: 15 | AB41: 20 | AC41: 0 | AD41: 0 | AE41: 14.423077 | AG41: 64.423077 | AH41: 0 | AI41: 80.528846 | AJ41: 80.528846
...

Sheet Engineers
A1: Engineer Code | B1: Engineer Name | C1: ASC Name | D1: Partner | E1: Service Type | F1: Status | G1: Product Group | H1: Dedicated / Non Dedicated | I1: Major / Minor | J1: Evaluation Target (Yes/No) | K1: SBA ID | L1: Product
A2: 7086001106 | B2: Loay Elabasy | C2: RAYA - GHARBEYA/ | D2: 3489862 | E2: IH | F2: Included | G2: AV | H2: Dedicated | I2: Above 30 | J2: Target | K2: GSPN.loay_elabasy24 | L2: AV
A3: 7886000279 | B3: Mohamed said | C3: NANOTEC/ | D3: 8351903 | E3: IH | F3: Excluded Q4 & Q1 | G3: HA | H3: Dedicated | I3: Below 20 | J3: Target | K3: GSPN.nanotechesa1 | L3: DA
A4: 7886000378 | B4: Mohamed Abdelrahman | C4: RAYA GIZA (HA)/ | D4: 9372701 | E4: PR | F4: Included | G4: HA | H4: Dedicated | I4: Above 20 | J4: Target | K4: GSPN.Mesha115 | L4: DA
A5: 7886000439 | B5: Mohamed Salah | C5: RAYA - GHARBEYA/ | D5: 3489862 | E5: IH | F5: Included | G5: AV | H5: Dedicated | I5: Above 30 | J5: Target | K5: GSPN.mohamed_salah24 | L5: AV
A6: 7886000482 | B6: 7886000482 | C6: RAYA - GHARBEYA/ | D6: 3489862 | E6: IH | F6: Included | G6: AV | H6: Dedicated | I6: Above 30 | J6: Target | K6: No SBA ID | L6: AV
A7: 7886000561 | B7: islam.2ct | C7: TO CONNECT SHOP/ | D7: 8396105 | E7: IH | F7: Excluded Tremiantion | G7: HA | H7: Dedicated | I7: Below 20 | J7: Target | K7: GSPN.islam.2ct | L7: DA
A8: 7886000617 | B8: 7886000617 | C8: JAPANESE CENTER FOR | D8: 9203505 | E8: IH | F8: Included | G8: AV | H8: Non Dedicated | I8: Below 20 | J8: Target | K8: No SBA ID | L8: AV
A9: 7886000632 | B9: Mohamed Ahmed | C9: EL MOHANDES SERVICE | D9: 8398383 | E9: IH | F9: Included | G9: AV | H9: Non Dedicated | I9: Below 20 | J9: Target | K9: GSPN.MohAhmed1 | L9: AV
A10: 7886000657 | B10: KABDELMSEH2000 | C10: RAYA GIZA (HA)/ | D10: 9372701 | E10: PR | F10: Included | G10: AV | H10: Dedicated | I10: Above 20 | J10: Target | K10: GSPN.KABDELMSEH2000 | L10: AV
A11: 7886000680 | B11: MICHAEL ADEL MALAK | C11: ADEL MALAK TERIAK/ | D11: 9203507 | E11: IH | F11: Included | G11: AV + HA | H11: Non Dedicated | I11: Below 20 | J11: Target | K11: GSPN.MICHAELADEL | L11: AV+DA
A12: 7886000751 | B12: Mohamed Hassan | C12: NANOTEC/ | D12: 8351903 | E12: CI | F12: Included | G12: HA | H12: Dedicated | I12: Below 20 | J12: Target | K12: GSPN.mohamedhassannano | L12: DA
... A118: 7886002844 | B118: Mohamed Abdelmoneem | C118: ELECTRA ASSUIT/ | D118: 4970875 | E118: IH | F118: Excluded Q4 & Q1 | G118: AV + HA | H118: Dedicated | I118: Below 20 | J118: Target | K118: GSPN.mmeneem2025 | L118: AV+DA

Sheet Quarterly Results
A1: Engineer Code | B1: Engineer Name | C1: Partner | D1: ASC Name | E1: Service Type | F1: Q1 Final Score | G1: Q1 SSR | H1: Q1 REDO | I1: Q1 Chatbot | J1: Q1 HASS | K1: Q1 Acc Core Parts | L1: Q1 Training Attendance | M1: Q1 Linkage Ratio | N1: Q2 Final Score | O1: Q2 RNPS | P1: Q2 REDO | Q1: Q2 Training Attendance | R1: Q2 ST Con | S1: Q2 MJ % | T1: Q2 Complete Repair | U1: Q2 Kahoot | V1: Q2 HASS | W1: Q2 Repair Volume | X1: Q3 Final Score | Y1: Q3 KPI 1 | Z1: Q3 KPI 2 | AA1: Q3 KPI 3 | AB1: Q3 KPI 4 | AC1: Q3 KPI 5 | AD1: Q3 KPI 6 | AE1: Q3 KPI 7 | AF1: Q3 KPI 8 | AG1: Q3 KPI 9 | AH1: Q4 Final Score | AI1: Q4 KPI 1 | AJ1: Q4 KPI 2 | AK1: Q4 KPI 3 | AL1: Q4 KPI 4 | AM1: Q4 KPI 5 | AN1: Q4 KPI 6 | AO1: Q4 KPI 7 | AP1: Q4 KPI 8 | AQ1: Q4 KPI 9
A2: 7086001106 | B2: Loay Elabasy | C2: 3489862 | D2: RAYA - GHARBEYA/ | E2: IH | F2: 75 | G2: 100 | H2: 100 | I2: 0 | J2: 0 | K2: 11.1111 | M2: 100 | N2: 81.25 | O2: 100 | P2: 100 | Q2: 100 | R2: 0 | S2: 100 | T2: 100 | W2: 81.25
A3: 7886000279 | B3: Mohamed said | C3: 8351903 | D3: NANOTEC/ | E3: IH | F3: 85 | G3: 100 | H3: 100 | I3: 0 | J3: 100 | K3: 0 | L3: 50 | M3: 100 | N3: 79.375 | O3: 100 | P3: 100 | Q3: 100 | R3: 10 | S3: 100 | T3: 0 | V3: 100 | W3: 64.375
A4: 7886000378 | B4: Mohamed Abdelrahman | C4: 9372701 | D4: RAYA GIZA (HA)/ | E4: PR | F4: 75 | G4: 100 | H4: 100 | I4: 0 | J4: 100 | K4: 0 | M4: 100 | N4: 15 | O4: 0 | P4: 100 | Q4: 100 | R4: 0 | S4: 5.9735 | T4: 0 | W4: 15
A5: 7886000439 | B5: Mohamed Salah | C5: 3489862 | D5: RAYA - GHARBEYA/ | E5: IH | F5: 60 | G5: 0 | H5: 100 | I5: 0 | J5: 0 | K5: 6.8182 | L5: 100 | M5: 100 | N5: 60.336538 | O5: 87.5 | P5: 0 | Q5: 100 | R5: 0 | S5: 100 | T5: 88.4615 | W5: 60.336538
A6: 7886000482 | B6: 7886000482 | C6: 3489862 | D6: RAYA - GHARBEYA/ | E6: IH | F6: 60 | G6: 100 | H6: 0 | I6: 0 | J6: 0 | K6: 0 | M6: 100 | N6: 37.5 | O6: 50 | P6: 0 | Q6: 100 | R6: 0 | S6: 100 | T6: 100 | W6: 37.5
A7: 7886000561 | B7: islam.2ct | C7: 8396105 | D7: TO CONNECT SHOP/ | E7: IH | F7: 75 | G7: 100 | H7: 100 | I7: 0 | J7: 100 | K7: 0 | M7: 100 | N7: 77.5 | O7: 100 | P7: 0 | Q7: 100 | R7: 0 | S7: 1.1062 | T7: 0 | V7: 100 | W7: 62.5
A8: 7886000617 | B8: 7886000617 | C8: 9203505 | D8: JAPANESE CENTER FOR | E8: IH | F8: 57 | G8: 100 | H8: 0 | I8: 0 | J8: 0 | K8: 75 | M8: 100 | N8: 33.75 | O8: -50 | P8: 100 | Q8: 100 | R8: 0 | S8: 100 | T8: 100 | W8: 33.75
A9: 7886000632 | B9: Mohamed Ahmed | C9: 8398383 | D9: EL MOHANDES SERVICE | E9: IH | F9: 75 | G9: 100 | H9: 100 | I9: 0 | J9: 0 | K9: 0 | L9: 0 | M9: 100 | N9: 95.3125 | O9: 100 | P9: 100 | Q9: 100 | R9: 0 | S9: 0.2212 | T9: 75 | W9: 95.3125
A10: 7886000657 | B10: KABDELMSEH2000 | C10: 9372701 | D10: RAYA GIZA (HA)/ | E10: PR | F10: 75 | G10: 100 | H10: 100 | I10: 0 | J10: 0 | K10: 0 | L10: 0 | M10: 100 | N10: 15 | O10: 0 | P10: 100 | Q10: 100 | R10: 0 | S10: 100 | T10: 0 | W10: 15
A11: 7886000680 | B11: MICHAEL ADEL MALAK | C11: 9203507 | D11: ADEL MALAK TERIAK/ | E11: IH | F11: 75 | G11: 100 | H11: 0 | I11: 0 | J11: 100 | K11: 0 | L11: 0 | M11: 100 | N11: 15 | O11: 0 | P11: 100 | Q11: 100 | R11: 0 | S11: 100 | T11: 0 | W11: 15
A12: 7886000751 | B12: Mohamed Hassan | C12: 8351903 | D12: NANOTEC/ | E12: CI | F12: 75 | G12: 100 | H12: 100 | I12: 0 | J12: 100 | K12: 0 | M12: 100 | N12: 15 | O12: 0 | P12: 100 | Q12: 100 | R12: 0 | S12: 100 | T12: 0 | W12: 15
A13: 7886000919 | B13: Mohamed Hussein | C13: 8396105 | D13: TO CONNECT SHOP/ | E13: IH | F13: 95 | G13: 100 | H13: 100 | I13: 0 | J13: 0 | K13: 11.1111 | L13: 100 | M13: 100 | N13: 78.125 | O13: 100 | P13: 100 | Q13: 100 | R13: 0 | S13: 100 | T13: 83.3333 | W13: 78.125
A14: 7886000930 | B14: Ahmed Hasan | C14: 8351903 | D14: NANOTEC/ | E14: IH | F14: 40 | G14: 100 | H14: 100 | I14: 0 | J14: 100 | K14: 0 | M14: 100 | N14: 52.5 | O14: 33.333333 | P14: 0 | Q14: 100 | R14: 0 | S14: 0.6637 | T14: 0 | V14: 100 | W14: 37.5
A15: 7886001034 | B15: ashraf abdrbo | C15: 9203499 | D15: HI TECH FOR MAINTENA | E15: IH | F15: 95 | G15: 100 | H15: 100 | I15: 0 | J15: 0 | K15: 0 | L15: 100 | M15: 100 | N15: 81.25 | O15: 100 | P15: 100 | Q15: 100 | R15: 0 | S15: 100 | T15: 100 | W15: 81.25
A16: 7886001053 | B16: Mohamed Salah | C16: 8396105 | D16: TO CONNECT SHOP/ | E16: IH | F16: 60 | G16: 100 | H16: 100 | I16: 0 | J16: 0 | K16: 0 | M16: 100 | N16: 77.5 | O16: 100 | P16: 0 | Q16: 100 | R16: 0 | S16: 0.2212 | T16: 0 | V16: 100 | W16: 62.5
A17: 7886001055 | B17: Ahmed Ramdan | C17: 9203499 | D17: HI TECH FOR MAINTENA | E17: IH | F17: 76.764706 | G17: 100 | H17: 100 | I17: 33.3 | J17: 66.6667 | K17: 0 | M17: 100 | N17: 91.5625 | O17: 100 | P17: 100 | Q17: 100 | R17: 0 | S17: 1.7699 | T17: 0 | V17: 68.75 | W17: 81.25
A18: 7886001214 | B18: 7886001214 | C18: 8351903 | D18: NANOTEC/ | E18: IH | F18: 75 | G18: 100 | H18: 100 | I18: 0 | J18: 100 | K18: 0 | M18: 100 | N18: 83 | O18: 100 | P18: 0 | Q18: 100 | R18: 0 | S18: 4.2035 | T18: 100 | V18: 95 | W18: 68.75
A19: 7886001393 | B19: MAHMOUD ZAHER | C19: 8215895 | D19: RAYA CAIRO/ | E19: IH | F19: 60 | G19: 0 | H19: 0 | I19: 100 | J19: 0 | K19: 1.9608 | L19: 100 | M19: 100 | N19: 81.25 | O19: 80.769231 | P19: 100 | Q19: 100 | R19: 0 | S19: 100 | T19: 100 | W19: 81.25
A20: 7886001399 | B20: HiTwabZag | C20: 9203499 | D20: HI TECH FOR MAINTENA | E20: IH | F20: 75 | G20: 100 | H20: 100 | I20: 100 | J20: 0 | K20: 0 | L20: 0 | M20: 100 | N20: 47.5 | O20: 100 | P20: 100 | Q20: 100 | R20: 0 | S20: 0.2212 | T20: 0 | V20: 100 | W20: 32.5
A21: 7886001633 | B21: MMsalim | C21: 2226596 | D21: TO CONNECT - NAG HAM | E21: IH | F21: 60 | G21: 100 | H21: 100 | I21: 0 | J21: 0 | K21: 0 | M21: 100 | N21: 15 | O21: 0 | P21: 100 | Q21: 100 | R21: 0 | S21: 100 | T21: 0 | W21: 15
A22: 7886001745 | B22: Ali Ismaiel Ali saied | C22: 8351903 | D22: NANOTEC/ | E22: IH | F22: 85 | G22: 100 | H22: 100 | I22: 66.7 | J22: 100 | K22: 0 | M22: 100 | N22: 66.477273 | O22: 20 | P22: 100 | Q22: 100 | R22: 0 | S22: 1.5487 | T22: 0 | V22: 68.1818 | W22: 56.25
A23: 7886001746 | B23: Mohamed Afify | C23: 8351903 | D23: NANOTEC/ | E23: IH | F23: 75 | G23: 100 | H23: 100 | I23: 0 | J23: 100 | K23: 0 | M23: 100 | N23: 95 | O23: 100 | P23: 100 | Q23: 100 | R23: 0 | S23: 0.885 | T23: 0 | V23: 91.6667 | W23: 81.25
A24: 7886001747 | B24: Salah Foaad | C24: 8351903 | D24: NANOTEC/ | E24: IH | F24: 60 | G24: 100 | H24: 0 | I24: 0 | J24: 100 | K24: 0 | M24: 100 | N24: 74.4375 | O24: 33.333333 | P24: 100 | Q24: 100 | R24: 25 | S24: 0.6637 | T24: 0 | V24: 90 | W24: 60.9375
A25: 7886001750 | B25: Hamed Ahmed | C25: 1390788 | D25: ATS BE - GREAT CAIRO | E25: IH | F25: 45 | G25: 0 | H25: 0 | I25: 0 | J25: 0 | K25: 10.1695 | L25: 100 | M25: 100 | N25: 80.528846 | O25: 77.5 | P25: 100 | Q25: 100 | R25: 0 | S25: 100 | T25: 96.1538 | W25: 80.528846
A26: 7886002009 | B26: Mokhtar Abdelrahim | C26: 8351903 | D26: NANOTEC/ | E26: IH | F26: 85 | G26: 100 | H26: 100 | I26: 66.7 | J26: 100 | K26: 0 | L26: 0 | M26: 100 | N26: 109.4697 | O26: 100 | P26: 100 | Q26: 100 | R26: 77.7778 | S26: 0.4425 | T26: 0 | V26: 90.9091 | W26: 95.833333
A27: 7886002061 | B27: nader diab nashed | C27: 2490932 | D27: ADEL CENTER BANI SUE | E27: IH | F27: 90 | G27: 100 | H27: 100 | I27: 0 | J27: 100 | K27: 0 | L27: 0 | M27: 100 | N27: 15 | O27: 0 | P27: 100 | Q27: 100 | R27: 0 | S27: 100 | T27: 0 | W27: 15
A28: 7886002084 | B28: Mohamed Mahros | C28: 8351903 | D28: NANOTEC/ | E28: IH | F28: 75 | G28: 100 | H28: 100 | I28: 0 | J28: 97.2973 | K28: 0 | M28: 100 | N28: 115 | O28: 100 | P28: 100 | Q28: 100 | R28: 100 | S28: 1.1062 | T28: 0 | V28: 100 | W28: 100
A29: 7886002099 | B29: Karem Saied | C29: 8351903 | D29: NANOTEC/ | E29: IH | F29: 85 | G29: 100 | H29: 100 | I29: 0 | J29: 0 | K29: 0 | L29: 50 | M29: 100 | N29: 81.25 | O29: 85.714286 | P29: 100 | Q29: 100 | R29: 0 | S29: 100 | T29: 100 | W29: 81.25
A30: 7886002136 | B30: Ahmed Salem | C30: 1390788 | D30: ATS BE - GREAT CAIRO | E30: IH | F30: 85 | G30: 100 | H30: 100 | I30: 0 | J30: 0 | K30: 20 | L30: 50 | M30: 100 | N30: 81.25 | O30: 100 | P30: 100 | Q30: 100 | R30: 0 | S30: 100 | T30: 100 | W30: 81.25
A31: 7886002144 | B31: Shady ElShayeb | C31: 9390474 | D31: EGYPTIAN MICRO SOLUT | E31: IH | F31: 95 | G31: 100 | H31: 100 | I31: 0 | J31: 0 | K31: 0 | L31: 100 | M31: 100 | N31: 37.5 | O31: 0 | P31: 100 | Q31: 100 | R31: 0 | S31: 100 | T31: 0 | W31: 37.5
A32: 7886002215 | B32: Karem Gamal | C32: 8351903 | D32: NANOTEC/ | E32: IH | F32: 75 | G32: 100 | H32: 100 | I32: 0 | J32: 97.5 | K32: 0 | M32: 100 | N32: 109.03409 | O32: 87.5 | P32: 100 | Q32: 100 | R32: 68.1818 | S32: 0.6637 | T32: 0 | V32: 100 | W32: 94.034091
A33: 7886002230 | B33: said.abdelraman1 | C33: 9372701 | D33: RAYA GIZA (HA)/ | E33: PR | F33: 25 | G33: 0 | H33: 0 | I33: 0 | J33: 0 | K33: 5.8824 | L33: 0 | M33: 100 | N33: 61.160714 | O33: 88.888889 | P33: 0 | Q33: 100 | R33: 0 | S33: 100 | T33: 92.8571 | V33: 0 | W33: 61.160714
A34: 7886002234 | B34: Khalid Mohammed | C34: 4162738 | D34: ELECTRA/ | E34: IH | F34: 70.588235 | G34: 100 | H34: 100 | I34: 0 | J34: 60 | K34: 0 | M34: 100 | N34: 32.5 | O34: 95.833333 | P34: 100 | Q34: 100 | R34: 0 | S34: 1.5487 | T34: 0 | V34: 0 | W34: 32.5
A35: 7886002272 | B35: Mohamed Shabban | C35: 1390788 | D35: ATS BE - GREAT CAIRO | E35: IH | F35: 60 | G35: 0 | H35: 100 | I35: 0 | J35: 0 | K35: 16 | L35: 100 | M35: 100 | N35: 78.229167 | O35: 65.217391 | P35: 100 | Q35: 100 | R35: 0 | S35: 100 | T35: 97.2222 | W35: 78.229167
A36: 7886002273 | B36: Ahmadbhaa | C36: 9203497 | D36: U TECH FOR SERVICE & | E36: IH | F36: 75 | G36: 100 | H36: 100 | I36: 0 | J36: 0 | K36: 0 | M36: 100 | N36: 15 | O36: 0 | P36: 100 | Q36: 100 | R36: 0 | S36: 100 | T36: 0 | W36: 15
A37: 7886002310 | B37: samir1saeed | C37: 2451952 | D37: U TECH SUEZ/BUILDING | E37: IH | F37: 73.235294 | G37: 100 | H37: 0 | I37: 0 | J37: 75 | K37: 0 | M37: 100 | N37: 15 | O37: 0 | P37: 100 | Q37: 100 | R37: 0 | S37: 100 | T37: 0 | W37: 15
A38: 7886002360 | B38: Osama Farouk | C38: 1390788 | D38: ATS BE - GREAT CAIRO | E38: PR | F38: 85 | G38: 100 | H38: 100 | I38: 0 | J38: 0 | K38: 0 | L38: 50 | M38: 100 | N38: 33.75 | O38: -66.666667 | P38: 100 | Q38: 100 | R38: 0 | S38: 100 | T38: 100 | W38: 33.75
A39: 7886002371 | B39: islam.emad01 | C39: 8215895 | D39: RAYA CAIRO/ | E39: IH | F39: 35 | G39: 0 | H39: 0 | I39: 0 | J39: 0 | K39: 0 | L39: 50 | M39: 100 | N39: 79.545455 | O39: 100 | P39: 100 | Q39: 100 | R39: 0 | S39: 100 | T39: 90.9091 | W39: 79.545455
A40: 7886002380 | B40: Mohamed.farouk01 | C40: 8215895 | D40: RAYA CAIRO/ | E40: IH | F40: 25 | G40: 0 | H40: 0 | I40: 0 | J40: 0 | K40: 0 | L40: 0 | M40: 100 | N40: 56.25 | O40: 50 | P40: 100 | Q40: 100 | R40: 0 | S40: 100 | T40: 100 | W40: 56.25
...

Sheet Summary
A1: Engineer Code | B1: Engineer Name | C1: Product | D1: Q1 Final Score | E1: Q2 Final Score | F1: Q3 Final Score | G1: Q4 Final Score | H1: Annual Average | I1: Best Quarter | J1: Worst Quarter | K1: Quarter Improvement | L1: Annual Rank
A2: 7086001106 | B2: Loay Elabasy | C2: AV | D2: =IF('Quarterly Results'!F2="","",'Quarterly Results'!F2) | E2: =IF('Quarterly Results'!N2="","",'Quarterly Results'!N2) | F2: =IF('Quarterly Results'!X2="","",'Quarterly Results'!X2) | G2: =IF('Quarterly Results'!AH2="","",'Quarterly Results'!AH2) | H2: =IFERROR(AVERAGEIF(D2:G2,">=0"),"") | I2: =IF(H2="","",IFERROR(INDEX({"Q1","Q2","Q3","Q4"},MATCH(MAX(D2:G2),D2:G2,0)),"")) | J2: =IF(H2="","",IFERROR(INDEX({"Q1","Q2","Q3","Q4"},MATCH(AGGREGATE(5,6,D2:G2),D2:G2,0)),"")) | K2: =IF(OR(D2="",E2=""),"",E2-D2) | L2: =IF(H2="","",RANK(H2,$H$2:$H$118,0))
A3: 7886000279 | B3: Mohamed said | C3: DA | D3: =IF('Quarterly Results'!F3="","",'Quarterly Results'!F3) | E3: =IF('Quarterly Results'!N3="","",'Quarterly Results'!N3) | F3: =IF('Quarterly Results'!X3="","",'Quarterly Results'!X3) | G3: =IF('Quarterly Results'!AH3="","",'Quarterly Results'!AH3) | H3: =IFERROR(AVERAGEIF(D3:G3,">=0"),"") | I3: =IF(H3="","",IFERROR(INDEX({"Q1","Q2","Q3","Q4"},MATCH(MAX(D3:G3),D3:G3,0)),"")) | J3: =IF(H3="","",IFERROR(INDEX({"Q1","Q2","Q3","Q4"},MATCH(AGGREGATE(5,6,D3:G3),D3:G3,0)),"")) | K3: =IF(OR(D3="",E3=""),"",E3-D3) | L3: =IF(H3="","",RANK(H3,$H$2:$H$118,0))
A4: 7886000378 | B4: Mohamed Abdelrahman | C4: DA | D4: =IF('Quarterly Results'!F4="","",'Quarterly Results'!F4) | E4: =IF('Quarterly Results'!N4="","",'Quarterly Results'!N4) | F4: =IF('Quarterly Results'!X4="","",'Quarterly Results'!X4) | G4: =IF('Quarterly Results'!AH4="","",'Quarterly Results'!AH4) | H4: =IFERROR(AVERAGEIF(D4:G4,">=0"),"") | I4: =IF(H4="","",IFERROR(INDEX({"Q1","Q2","Q3","Q4"},MATCH(MAX(D4:G4),D4:G4,0)),"")) | J4: =IF(H4="","",IFERROR(INDEX({"Q1","Q2","Q3","Q4"},MATCH(AGGREGATE(5,6,D4:G4),D4:G4,0)),"")) | K4: =IF(OR(D4="",E4=""),"",E4-D4) | L4: =IF(H4="","",RANK(H4,$H$2:$H$118,0))
A5: 7886000439 | B5: Mohamed Salah | C5: AV | D5: =IF('Quarterly Results'!F5="","",'Quarterly Results'!F5) | E5: =IF('Quarterly Results'!N5="","",'Quarterly Results'!N5) | F5: =IF('Quarterly Results'!X5="","",'Quarterly Results'!X5) | G5: =IF('Quarterly Results'!AH5="","",'Quarterly Results'!AH5) | H5: =IFERROR(AVERAGEIF(D5:G5,">=0"),"") | I5: =IF(H5="","",IFERROR(INDEX({"Q1","Q2","Q3","Q4"},MATCH(MAX(D5:G5),D5:G5,0)),"")) | J5: =IF(H5="","",IFERROR(INDEX({"Q1","Q2","Q3","Q4"},MATCH(AGGREGATE(5,6,D5:G5),D5:G5,0)),"")) | K5: =IF(OR(D5="",E5=""),"",E5-D5) | L5: =IF(H5="","",RANK(H5,$H$2:$H$118,0))
A6: 7886000482 | B6: 7886000482 | C6: AV | D6: =IF('Quarterly Results'!F6="","",'Quarterly Results'!F6) | E6: =IF('Quarterly Results'!N6="","",'Quarterly Results'!N6) | F6: =IF('Quarterly Results'!X6="","",'Quarterly Results'!X6) | G6: =IF('Quarterly Results'!AH6="","",'Quarterly Results'!AH6) | H6: =IFERROR(AVERAGEIF(D6:G6,">=0"),"") | I6: =IF(H6="","",IFERROR(INDEX({"Q1","Q2","Q3","Q4"},MATCH(MAX(D6:G6),D6:G6,0)),"")) | J6: =IF(H6="","",IFERROR(INDEX({"Q1","Q2","Q3","Q4"},MATCH(AGGREGATE(5,6,D6:G6),D6:G6,0)),"")) | K6: =IF(OR(D6="",E6=""),"",E6-D6) | L6: =IF(H6="","",RANK(H6,$H$2:$H$118,0))
A7: 7886000561 | B7: islam.2ct | C7: DA | D7: =IF('Quarterly Results'!F7="","",'Quarterly Results'!F7) | E7: =IF('Quarterly Results'!N7="","",'Quarterly Results'!N7) | F7: =IF('Quarterly Results'!X7="","",'Quarterly Results'!X7) | G7: =IF('Quarterly Results'!AH7="","",'Quarterly Results'!AH7) | H7: =IFERROR(AVERAGEIF(D7:G7,">=0"),"") | I7: =IF(H7="","",IFERROR(INDEX({"Q1","Q2","Q3","Q4"},MATCH(MAX(D7:G7),D7:G7,0)),"")) | J7: =IF(H7="","",IFERROR(INDEX({"Q1","Q2","Q3","Q4"},MATCH(AGGREGATE(5,6,D7:G7),D7:G7,0)),"")) | K7: =IF(OR(D7="",E7=""),"",E7-D7) | L7: =IF(H7="","",RANK(H7,$H$2:$H$118,0))
A8: 7886000617 | B8: 7886000617 | C8: AV | D8: =IF('Quarterly Results'!F8="","",'Quarterly Results'!F8) | E8: =IF('Quarterly Results'!N8="","",'Quarterly Results'!N8) | F8: =IF('Quarterly Results'!X8="","",'Quarterly Results'!X8) | G8: =IF('Quarterly Results'!AH8="","",'Quarterly Results'!AH8) | H8: =IFERROR(AVERAGEIF(D8:G8,">=0"),"") | I8: =IF(H8="","",IFERROR(INDEX({"Q1","Q2","Q3","Q4"},MATCH(MAX(D8:G8),D8:G8,0)),"")) | J8: =IF(H8="","",IFERROR(INDEX({"Q1","Q2","Q3","Q4"},MATCH(AGGREGATE(5,6,D8:G8),D8:G8,0)),"")) | K8: =IF(OR(D8="",E8=""),"",E8-D8) | L8: =IF(H8="","",RANK(H8,$H$2:$H$118,0))
A9: 7886000632 | B9: Mohamed Ahmed | C9: AV | D9: =IF('Quarterly Results'!F9="","",'Quarterly Results'!F9) | E9: =IF('Quarterly Results'!N9="","",'Quarterly Results'!N9) | F9: =IF('Quarterly Results'!X9="","",'Quarterly Results'!X9) | G9: =IF('Quarterly Results'!AH9="","",'Quarterly Results'!AH9) | H9: =IFERROR(AVERAGEIF(D9:G9,">=0"),"") | I9: =IF(H9="","",IFERROR(INDEX({"Q1","Q2","Q3","Q4"},MATCH(MAX(D9:G9),D9:G9,0)),"")) | J9: =IF(H9="","",IFERROR(INDEX({"Q1","Q2","Q3","Q4"},MATCH(AGGREGATE(5,6,D9:G9),D9:G9,0)),"")) | K9: =IF(OR(D9="",E9=""),"",E9-D9) | L9: =IF(H9="","",RANK(H9,$H$2:$H$118,0))
A10: 7886000657 | B10: KABDELMSEH2000 | C10: AV | D10: =IF('Quarterly Results'!F10="","",'Quarterly Results'!F10) | E10: =IF('Quarterly Results'!N10="","",'Quarterly Results'!N10) | F10: =IF('Quarterly Results'!X10="","",'Quarterly Results'!X10) | G10: =IF('Quarterly Results'!AH10="","",'Quarterly Results'!AH10) | H10: =IFERROR(AVERAGEIF(D10:G10,">=0"),"") | I10: =IF(H10="","",IFERROR(INDEX({"Q1","Q2","Q3","Q4"},MATCH(MAX(D10:G10),D10:G10,0)),"")) | J10: =IF(H10="","",IFERROR(INDEX({"Q1","Q2","Q3","Q4"},MATCH(AGGREGATE(5,6,D10:G10),D10:G10,0)),"")) | K10: =IF(OR(D10="",E10=""),"",E10-D10) | L10: =IF(H10="","",RANK(H10,$H$2:$H$118,0))
A11: 7886000680 | B11: MICHAEL ADEL MALAK | C11: AV+DA | D11: =IF('Quarterly Results'!F11="","",'Quarterly Results'!F11) | E11: =IF('Quarterly Results'!N11="","",'Quarterly Results'!N11) | F11: =IF('Quarterly Results'!X11="","",'Quarterly Results'!X11) | G11: =IF('Quarterly Results'!AH11="","",'Quarterly Results'!AH11) | H11: =IFERROR(AVERAGEIF(D11:G11,">=0"),"") | I11: =IF(H11="","",IFERROR(INDEX({"Q1","Q2","Q3","Q4"},MATCH(MAX(D11:G11),D11:G11,0)),"")) | J11: =IF(H11="","",IFERROR(INDEX({"Q1","Q2","Q3","Q4"},MATCH(AGGREGATE(5,6,D11:G11),D11:G11,0)),"")) | K11: =IF(OR(D11="",E11=""),"",E11-D11) | L11: =IF(H11="","",RANK(H11,$H$2:$H$118,0))
A12: 7886000751 | B12: Mohamed Hassan | C12: DA | D12: =IF('Quarterly Results'!F12="","",'Quarterly Results'!F12) | E12: =IF('Quarterly Results'!N12="","",'Quarterly Results'!N12) | F12: =IF('Quarterly Results'!X12="","",'Quarterly Results'!X12) | G12: =IF('Quarterly Results'!AH12="","",'Quarterly Results'!AH12) | H12: =IFERROR(AVERAGEIF(D12:G12,">=0"),"") | I12: =IF(H12="","",IFERROR(INDEX({"Q1","Q2","Q3","Q4"},MATCH(MAX(D12:G12),D12:G12,0)),"")) | J12: =IF(H12="","",IFERROR(INDEX({"Q1","Q2","Q3","Q4"},MATCH(AGGREGATE(5,6,D12:G12),D12:G12,0)),"")) | K12: =IF(OR(D12="",E12=""),"",E12-D12) | L12: =IF(H12="","",RANK(H12,$H$2:$H$118,0))
A13: 7886000919 | B13: Mohamed Hussein | C13: AV | D13: =IF('Quarterly Results'!F13="","",'Quarterly Results'!F13) | E13: =IF('Quarterly Results'!N13="","",'Quarterly Results'!N13) | F13: =IF('Quarterly Results'!X13="","",'Quarterly Results'!X13) | G13: =IF('Quarterly Results'!AH13="","",'Quarterly Results'!AH13) | H13: =IFERROR(AVERAGEIF(D13:G13,">=0"),"") | I13: =IF(H13="","",IFERROR(INDEX({"Q1","Q2","Q3","Q4"},MATCH(MAX(D13:G13),D13:G13,0)),"")) | J13: =IF(H13="","",IFERROR(INDEX({"Q1","Q2","Q3","Q4"},MATCH(AGGREGATE(5,6,D13:G13),D13:G13,0)),"")) | K13: =IF(OR(D13="",E13=""),"",E13-D13) | L13: =IF(H13="","",RANK(H13,$H$2:$H$118,0))
... A118: 7886002844 | B118: Mohamed Abdelmoneem | C118: AV+DA | D118: =IF('Quarterly Results'!F118="","",'Quarterly Results'!F118) | E118: =IF('Quarterly Results'!N118="","",'Quarterly Results'!N118) | F118: =IF('Quarterly Results'!X118="","",'Quarterly Results'!X118) | G118: =IF('Quarterly Results'!AH118="","",'Quarterly Results'!AH118) | H118: =IFERROR(AVERAGEIF(D118:G118,">=0"),"") | I118: =IF(H118="","",IFERROR(INDEX({"Q1","Q2","Q3","Q4"},MATCH(MAX(D118:G118),D118:G118,0)),"")) | J118: =IF(H118="","",IFERROR(INDEX({"Q1","Q2","Q3","Q4"},MATCH(AGGREGATE(5,6,D118:G118),D118:G118,0)),"")) | K118: =IF(OR(D118="",E118=""),"",E118-D118) | L118: =IF(H118="","",RANK(H118,$H$2:$H$118,0))

Sheet ReadMe
A1: DA-AV Engineer Performance Master 2026
A3: Primary key | B3: Engineer Code (numeric SBA engineer id)
A4: Source preserved | B4: SRC Q1 2026 winners / SRC Q2 Engineer Eval (untouched copies)
A5: App sheets | B5: Engineers · Quarterly Results · Summary
A6: Q1 KPIs | B6: Q1 Final Score | Q1 SSR | Q1 REDO | Q1 Chatbot | Q1 HASS | Q1 Acc Core Parts | Q1 Training Attendance | Q1 Linkage Ratio
A7: Q2 KPIs | B7: Q2 Final Score | Q2 RNPS | Q2 REDO | Q2 Training Attendance | Q2 ST Con | Q2 MJ % | Q2 Complete Repair | Q2 Kahoot | Q2 HASS | Q2 Repair Volume
A8: Future | B8: Fill Q3 / Q4 Final Score + KPI columns — no structural redesign needed
A9: Product | B9: HA → DA, AV → AV, AV + HA → AV+DA (Product column on Engineers)
A10: Scores | B10: Existing finals may exceed 100 due to bonuses; validation allows 0–200
A11: Generated | B11: 2026-07-30T04:03:16.473Z
